Workbook
Name Slicer_Month: #N/A
Name Slicer_Month1: #N/A
Name Slicer_Month2: #N/A

Sheet Charge
A1: Charge_id | B1: Subscription ID | C1: Customer ID | D1: Charge Date | E1: Amount | F1: Status | G1: Payment Method
A2: CHG95000 | B2: SUB8003 | C2: CUS4626 | D2: 45505 | E2: 999 | F2: Paid | G2: Card
A3: CHG95001 | B3: SUB8003 | C3: CUS4626 | D3: 45536 | E3: 999 | F3: Paid | G3: Card
A4: CHG95002 | B4: SUB8004 | C4: CUS4128 | D4: 45507 | E4: 2499 | F4: Paid | G4: Card
A5: CHG95003 | B5: SUB8004 | C5: CUS4128 | D5: 45539 | E5: 2499 | F5: Paid | G5: Card
A6: CHG95004 | B6: SUB8005 | C6: CUS4019 | D6: 45326 | E6: 999 | F6: Paid | G6: Card
A7: CHG95005 | B7: SUB8005 | C7: CUS4019 | D7: 45353 | E7: 999 | F7: Paid | G7: Card
A8: CHG95006 | B8: SUB8005 | C8: CUS4019 | D8: 45383 | E8: 999 | F8: Paid | G8: Card
A9: CHG95007 | B9: SUB8005 | C9: CUS4019 | D9: 45415 | E9: 999 | F9: Paid | G9: PayPal
A10: CHG95008 | B10: SUB8005 | C10: CUS4019 | D10: 45444 | E10: 999 | F10: Paid | G10: UPI
A11: CHG95009 | B11: SUB8005 | C11: CUS4019 | D11: 45476 | E11: 999 | F11: Paid | G11: Card
A12: CHG95010 | B12: SUB8005 | C12: CUS4019 | D12: 45508 | E12: 999 | F12: Paid | G12: Card
A13: CHG95011 | B13: SUB8005 | C13: CUS4019 | D13: 45537 | E13: 999 | F13: Paid | G13: Card
... A4006: CHG99004 | B4006: SUB9199 | C4006: CUS4062 | D4006: 45538 | E4006: 2499 | F4006: Paid | G4006: Wire

Sheet Subscription
A1: Subscription ID | B1: Customer ID | C1: Plan Type | D1: Monthly Price | E1: Subscription Start | F1: Subscription Status | G1: Churn Date | H1: Active | I1: New | J1: Churned | K1: Month | L1: Satrt Date | M1: End Date | N1: 1 For Active | O1: 2 For Active | P1: Month2
A2: SUB8191 | B2: CUS4528 | C2: Pro | D2: 2499 | E2: 45558 | F2: Active | H2: =IF(AND(E2 <= $M2, OR(G2 = "", G2 > $M2)), "Yes", "No") -> Yes | I2: =IF(AND(E2>=$M2,E2<=$M2),"Yes","No") -> No | J2: =IF(AND(G2<> " ",G2>=$L2,G2<=$M2),"Yes","No") -> No | K2: =MONTH(Table2[[#This Row],[Subscription Start]]) -> 9 | L2: =DATE(2024,Table2[[#This Row],[Month]],1) -> 45536 | M2: =DATE(2024,Table2[[#This Row],[Month]],30) -> 45565 | N2: =IF(Table2[[#This Row],[Active]]="Yes",1,0) -> 1 | O2: =IF(Table2[[#This Row],[Churned]]="Yes",1,0) -> 0 | P2: Sep
A3: SUB9172 | B3: CUS4058 | C3: Basic | D3: 999 | E3: 45557 | F3: Active | H3: =IF(AND(E3 <= $M3, OR(G3 = "", G3 > $M3)), "Yes", "No") -> Yes | I3: =IF(AND(E3>=$M3,E3<=$M3),"Yes","No") -> No | J3: =IF(AND(G3<> " ",G3>=$L3,G3<=$M3),"Yes","No") -> No | K3: =MONTH(Table2[[#This Row],[Subscription Start]]) -> 9 | L3: =DATE(2024,Table2[[#This Row],[Month]],1) -> 45536 | M3: =DATE(2024,Table2[[#This Row],[Month]],30) -> 45565 | N3: =IF(Table2[[#This Row],[Active]]="Yes",1,0) -> 1 | O3: =IF(Table2[[#This Row],[Churned]]="Yes",1,0) -> 0 | P3: Sep
A4: SUB8240 | B4: CUS4788 | C4: Basic | D4: 999 | E4: 45556 | F4: Canceled | G4: 45565 | H4: =IF(AND(E4 <= $M4, OR(G4 = "", G4 > $M4)), "Yes", "No") -> No | I4: =IF(AND(E4>=$M4,E4<=$M4),"Yes","No") -> No | J4: =IF(AND(G4<> " ",G4>=$L4,G4<=$M4),"Yes","No") -> Yes | K4: =MONTH(Table2[[#This Row],[Subscription Start]]) -> 9 | L4: =DATE(2024,Table2[[#This Row],[Month]],1) -> 45536 | M4: =DATE(2024,Table2[[#This Row],[Month]],30) -> 45565 | N4: =IF(Table2[[#This Row],[Active]]="Yes",1,0) -> 0 | O4: =IF(Table2[[#This Row],[Churned]]="Yes",1,0) -> 1 | P4: Sep
A5: SUB8440 | B5: CUS4621 | C5: Pro | D5: 2499 | E5: 45555 | F5: Canceled | G5: 45565 | H5: =IF(AND(E5 <= $M5, OR(G5 = "", G5 > $M5)), "Yes", "No") -> No | I5: =IF(AND(E5>=$M5,E5<=$M5),"Yes","No") -> No | J5: =IF(AND(G5<> " ",G5>=$L5,G5<=$M5),"Yes","No") -> Yes | K5: =MONTH(Table2[[#This Row],[Subscription Start]]) -> 9 | L5: =DATE(2024,Table2[[#This Row],[Month]],1) -> 45536 | M5: =DATE(2024,Table2[[#This Row],[Month]],30) -> 45565 | N5: =IF(Table2[[#This Row],[Active]]="Yes",1,0) -> 0 | O5: =IF(Table2[[#This Row],[Churned]]="Yes",1,0) -> 1 | P5: Sep
A6: SUB8217 | B6: CUS4383 | C6: Basic | D6: 999 | E6: 45553 | F6: Active | H6: =IF(AND(E6 <= $M6, OR(G6 = "", G6 > $M6)), "Yes", "No") -> Yes | I6: =IF(AND(E6>=$M6,E6<=$M6),"Yes","No") -> No | J6: =IF(AND(G6<> " ",G6>=$L6,G6<=$M6),"Yes","No") -> No | K6: =MONTH(Table2[[#This Row],[Subscription Start]]) -> 9 | L6: =DATE(2024,Table2[[#This Row],[Month]],1) -> 45536 | M6: =DATE(2024,Table2[[#This Row],[Month]],30) -> 45565 | N6: =IF(Table2[[#This Row],[Active]]="Yes",1,0) -> 1 | O6: =IF(Table2[[#This Row],[Churned]]="Yes",1,0) -> 0 | P6: Sep
A7: SUB8277 | B7: CUS4627 | C7: Basic | D7: 999 | E7: 45553 | F7: Active | H7: =IF(AND(E7 <= $M7, OR(G7 = "", G7 > $M7)), "Yes", "No") -> Yes | I7: =IF(AND(E7>=$M7,E7<=$M7),"Yes","No") -> No | J7: =IF(AND(G7<> " ",G7>=$L7,G7<=$M7),"Yes","No") -> No | K7: =MONTH(Table2[[#This Row],[Subscription Start]]) -> 9 | L7: =DATE(2024,Table2[[#This Row],[Month]],1) -> 45536 | M7: =DATE(2024,Table2[[#This Row],[Month]],30) -> 45565 | N7: =IF(Table2[[#This Row],[Active]]="Yes",1,0) -> 1 | O7: =IF(Table2[[#This Row],[Churned]]="Yes",1,0) -> 0 | P7: Sep | R7: Sep
A8: SUB8538 | B8: CUS4577 | C8: Enterprise | D8: 9999 | E8: 45553 | F8: Canceled | G8: 45565 | H8: =IF(AND(E8 <= $M8, OR(G8 = "", G8 > $M8)), "Yes", "No") -> No | I8: =IF(AND(E8>=$M8,E8<=$M8),"Yes","No") -> No | J8: =IF(AND(G8<> " ",G8>=$L8,G8<=$M8),"Yes","No") -> Yes | K8: =MONTH(Table2[[#This Row],[Subscription Start]]) -> 9 | L8: =DATE(2024,Table2[[#This Row],[Month]],1) -> 45536 | M8: =DATE(2024,Table2[[#This Row],[Month]],30) -> 45565 | N8: =IF(Table2[[#This Row],[Active]]="Yes",1,0) -> 0 | O8: =IF(Table2[[#This Row],[Churned]]="Yes",1,0) -> 1 | P8: Sep | R8: Sep
A9: SUB8792 | B9: CUS4437 | C9: Basic | D9: 999 | E9: 45553 | F9: Active | H9: =IF(AND(E9 <= $M9, OR(G9 = "", G9 > $M9)), "Yes", "No") -> Yes | I9: =IF(AND(E9>=$M9,E9<=$M9),"Yes","No") -> No | J9: =IF(AND(G9<> " ",G9>=$L9,G9<=$M9),"Yes","No") -> No | K9: =MONTH(Table2[[#This Row],[Subscription Start]]) -> 9 | L9: =DATE(2024,Table2[[#This Row],[Month]],1) -> 45536 | M9: =DATE(2024,Table2[[#This Row],[Month]],30) -> 45565 | N9: =IF(Table2[[#This Row],[Active]]="Yes",1,0) -> 1 | O9: =IF(Table2[[#This Row],[Churned]]="Yes",1,0) -> 0 | P9: Sep | R9: Sep
A10: SUB8200 | B10: CUS4271 | C10: Pro | D10: 2499 | E10: 45552 | F10: Active | H10: =IF(AND(E10 <= $M10, OR(G10 = "", G10 > $M10)), "Yes", "No") -> Yes | I10: =IF(AND(E10>=$M10,E10<=$M10),"Yes","No") -> No | J10: =IF(AND(G10<> " ",G10>=$L10,G10<=$M10),"Yes","No") -> No | K10: =MONTH(Table2[[#This Row],[Subscription Start]]) -> 9 | L10: =DATE(2024,Table2[[#This Row],[Month]],1) -> 45536 | M10: =DATE(2024,Table2[[#This Row],[Month]],30) -> 45565 | N10: =IF(Table2[[#This Row],[Active]]="Yes",1,0) -> 1 | O10: =IF(Table2[[#This Row],[Churned]]="Yes",1,0) -> 0 | P10: Sep | R10: Sep
A11: SUB8630 | B11: CUS4292 | C11: Free | D11: 0 | E11: 45552 | F11: Active | H11: =IF(AND(E11 <= $M11, OR(G11 = "", G11 > $M11)), "Yes", "No") -> Yes | I11: =IF(AND(E11>=$M11,E11<=$M11),"Yes","No") -> No | J11: =IF(AND(G11<> " ",G11>=$L11,G11<=$M11),"Yes","No") -> No | K11: =MONTH(Table2[[#This Row],[Subscription Start]]) -> 9 | L11: =DATE(2024,Table2[[#This Row],[Month]],1) -> 45536 | M11: =DATE(2024,Table2[[#This Row],[Month]],30) -> 45565 | N11: =IF(Table2[[#This Row],[Active]]="Yes",1,0) -> 1 | O11: =IF(Table2[[#This Row],[Churned]]="Yes",1,0) -> 0 | P11: Sep
A12: SUB8821 | B12: CUS4039 | C12: Pro | D12: 2499 | E12: 45552 | F12: Canceled | G12: 45565 | H12: =IF(AND(E12 <= $M12, OR(G12 = "", G12 > $M12)), "Yes", "No") -> No | I12: =IF(AND(E12>=$M12,E12<=$M12),"Yes","No") -> No | J12: =IF(AND(G12<> " ",G12>=$L12,G12<=$M12),"Yes","No") -> Yes | K12: =MONTH(Table2[[#This Row],[Subscription Start]]) -> 9 | L12: =DATE(2024,Table2[[#This Row],[Month]],1) -> 45536 | M12: =DATE(2024,Table2[[#This Row],[Month]],30) -> 45565 | N12: =IF(Table2[[#This Row],[Active]]="Yes",1,0) -> 0 | O12: =IF(Table2[[#This Row],[Churned]]="Yes",1,0) -> 1 | P12: Sep | AB12: Month | AC12: Start | AD12: End
A13: SUB9046 | B13: CUS4170 | C13: Free | D13: 0 | E13: 45552 | F13: Active | H13: =IF(AND(E13 <= $M13, OR(G13 = "", G13 > $M13)), "Yes", "No") -> Yes | I13: =IF(AND(E13>=$M13,E13<=$M13),"Yes","No") -> No | J13: =IF(AND(G13<> " ",G13>=$L13,G13<=$M13),"Yes","No") -> No | K13: =MONTH(Table2[[#This Row],[Subscription Start]]) -> 9 | L13: =DATE(2024,Table2[[#This Row],[Month]],1) -> 45536 | M13: =DATE(2024,Table2[[#This Row],[Month]],30) -> 45565 | N13: =IF(Table2[[#This Row],[Active]]="Yes",1,0) -> 1 | O13: =IF(Table2[[#This Row],[Churned]]="Yes",1,0) -> 0 | P13: Sep | AB13: 45292 | AC13: 45292 | AD13: 45322
A14: SUB8645 | B14: CUS4091 | C14: Free | D14: 0 | E14: 45551 | F14: Active | H14: =IF(AND(E14 <= $M14, OR(G14 = "", G14 > $M14)), "Yes", "No") -> Yes | I14: =IF(AND(E14>=$M14,E14<=$M14),"Yes","No") -> No | J14: =IF(AND(G14<> " ",G14>=$L14,G14<=$M14),"Yes","No") -> No | K14: =MONTH(Table2[[#This Row],[Subscription Start]]) -> 9 | L14: =DATE(2024,Table2[[#This Row],[Month]],1) -> 45536 | M14: =DATE(2024,Table2[[#This Row],[Month]],30) -> 45565 | N14: =IF(Table2[[#This Row],[Active]]="Yes",1,0) -> 1 | O14: =IF(Table2[[#This Row],[Churned]]="Yes",1,0) -> 0 | P14: Sep | AB14: 45323 | AC14: 45323 | AD14: 45351
A15: SUB9193 | B15: CUS4437 | C15: Basic | D15: 999 | E15: 45551 | F15: Active | H15: =IF(AND(E15 <= $M15, OR(G15 = "", G15 > $M15)), "Yes", "No") -> Yes | I15: =IF(AND(E15>=$M15,E15<=$M15),"Yes","No") -> No | J15: =IF(AND(G15<> " ",G15>=$L15,G15<=$M15),"Yes","No") -> No | K15: =MONTH(Table2[[#This Row],[Subscription Start]]) -> 9 | L15: =DATE(2024,Table2[[#This Row],[Month]],1) -> 45536 | M15: =DATE(2024,Table2[[#This Row],[Month]],30) -> 45565 | N15: =IF(Table2[[#This Row],[Active]]="Yes",1,0) -> 1 | O15: =IF(Table2[[#This Row],[Churned]]="Yes",1,0) -> 0 | P15: Sep | AB15: 45352 | AC15: 45717 | AD15: 45382
A16: SUB8291 | B16: CUS4383 | C16: Basic | D16: 999 | E16: 45549 | F16: Canceled | G16: 45565 | H16: =IF(AND(E16 <= $M16, OR(G16 = "", G16 > $M16)), "Yes", "No") -> No | I16: =IF(AND(E16>=$M16,E16<=$M16),"Yes","No") -> No | J16: =IF(AND(G16<> " ",G16>=$L16,G16<=$M16),"Yes","No") -> Yes | K16: =MONTH(Table2[[#This Row],[Subscription Start]]) -> 9 | L16: =DATE(2024,Table2[[#This Row],[Month]],1) -> 45536 | M16: =DATE(2024,Table2[[#This Row],[Month]],30) -> 45565 | N16: =IF(Table2[[#This Row],[Active]]="Yes",1,0) -> 0 | O16: =IF(Table2[[#This Row],[Churned]]="Yes",1,0) -> 1 | P16: Sep | AB16: 45383 | AC16: 45383 | AD16: 45412
A17: SUB8506 | B17: CUS4058 | C17: Free | D17: 0 | E17: 45549 | F17: Active | H17: =IF(AND(E17 <= $M17, OR(G17 = "", G17 > $M17)), "Yes", "No") -> Yes | I17: =IF(AND(E17>=$M17,E17<=$M17),"Yes","No") -> No | J17: =IF(AND(G17<> " ",G17>=$L17,G17<=$M17),"Yes","No") -> No | K17: =MONTH(Table2[[#This Row],[Subscription Start]]) -> 9 | L17: =DATE(2024,Table2[[#This Row],[Month]],1) -> 45536 | M17: =DATE(2024,Table2[[#This Row],[Month]],30) -> 45565 | N17: =IF(Table2[[#This Row],[Active]]="Yes",1,0) -> 1 | O17: =IF(Table2[[#This Row],[Churned]]="Yes",1,0) -> 0 | P17: Sep | AB17: 45413 | AC17: 45413 | AD17: 45443
A18: SUB8988 | B18: CUS4058 | C18: Basic | D18: 999 | E18: 45549 | F18: Active | H18: =IF(AND(E18 <= $M18, OR(G18 = "", G18 > $M18)), "Yes", "No") -> Yes | I18: =IF(AND(E18>=$M18,E18<=$M18),"Yes","No") -> No | J18: =IF(AND(G18<> " ",G18>=$L18,G18<=$M18),"Yes","No") -> No | K18: =MONTH(Table2[[#This Row],[Subscription Start]]) -> 9 | L18: =DATE(2024,Table2[[#This Row],[Month]],1) -> 45536 | M18: =DATE(2024,Table2[[#This Row],[Month]],30) -> 45565 | N18: =IF(Table2[[#This Row],[Active]]="Yes",1,0) -> 1 | O18: =IF(Table2[[#This Row],[Churned]]="Yes",1,0) -> 0 | P18: Sep | AB18: 45444 | AC18: 45444 | AD18: 45473
A19: SUB9111 | B19: CUS4427 | C19: Basic | D19: 999 | E19: 45549 | F19: Active | H19: =IF(AND(E19 <= $M19, OR(G19 = "", G19 > $M19)), "Yes", "No") -> Yes | I19: =IF(AND(E19>=$M19,E19<=$M19),"Yes","No") -> No | J19: =IF(AND(G19<> " ",G19>=$L19,G19<=$M19),"Yes","No") -> No | K19: =MONTH(Table2[[#This Row],[Subscription Start]]) -> 9 | L19: =DATE(2024,Table2[[#This Row],[Month]],1) -> 45536 | M19: =DATE(2024,Table2[[#This Row],[Month]],30) -> 45565 | N19: =IF(Table2[[#This Row],[Active]]="Yes",1,0) -> 1 | O19: =IF(Table2[[#This Row],[Churned]]="Yes",1,0) -> 0 | P19: Sep | AB19: 45474 | AC19: 45474 | AD19: 45504
A20: SUB8234 | B20: CUS4271 | C20: Free | D20: 0 | E20: 45548 | F20: Active | H20: =IF(AND(E20 <= $M20, OR(G20 = "", G20 > $M20)), "Yes", "No") -> Yes | I20: =IF(AND(E20>=$M20,E20<=$M20),"Yes","No") -> No | J20: =IF(AND(G20<> " ",G20>=$L20,G20<=$M20),"Yes","No") -> No | K20: =MONTH(Table2[[#This Row],[Subscription Start]]) -> 9 | L20: =DATE(2024,Table2[[#This Row],[Month]],1) -> 45536 | M20: =DATE(2024,Table2[[#This Row],[Month]],30) -> 45565 | N20: =IF(Table2[[#This Row],[Active]]="Yes",1,0) -> 1 | O20: =IF(Table2[[#This Row],[Churned]]="Yes",1,0) -> 0 | P20: Sep | AB20: 45505 | AC20: 45505 | AD20: 45535
A21: SUB8297 | B21: CUS4439 | C21: Basic | D21: 999 | E21: 45548 | F21: Active | H21: =IF(AND(E21 <= $M21, OR(G21 = "", G21 > $M21)), "Yes", "No") -> Yes | I21: =IF(AND(E21>=$M21,E21<=$M21),"Yes","No") -> No | J21: =IF(AND(G21<> " ",G21>=$L21,G21<=$M21),"Yes","No") -> No | K21: =MONTH(Table2[[#This Row],[Subscription Start]]) -> 9 | L21: =DATE(2024,Table2[[#This Row],[Month]],1) -> 45536 | M21: =DATE(2024,Table2[[#This Row],[Month]],30) -> 45565 | N21: =IF(Table2[[#This Row],[Active]]="Yes",1,0) -> 1 | O21: =IF(Table2[[#This Row],[Churned]]="Yes",1,0) -> 0 | P21: Sep | AB21: 45536 | AC21: 45536 | AD21: 45565
A22: SUB8834 | B22: CUS4058 | C22: Pro | D22: 2499 | E22: 45547 | F22: Active | H22: =IF(AND(E22 <= $M22, OR(G22 = "", G22 > $M22)), "Yes", "No") -> Yes | I22: =IF(AND(E22>=$M22,E22<=$M22),"Yes","No") -> No | J22: =IF(AND(G22<> " ",G22>=$L22,G22<=$M22),"Yes","No") -> No | K22: =MONTH(Table2[[#This Row],[Subscription Start]]) -> 9 | L22: =DATE(2024,Table2[[#This Row],[Month]],1) -> 45536 | M22: =DATE(2024,Table2[[#This Row],[Month]],30) -> 45565 | N22: =IF(Table2[[#This Row],[Active]]="Yes",1,0) -> 1 | O22: =IF(Table2[[#This Row],[Churned]]="Yes",1,0) -> 0 | P22: Sep | AB22: 45566 | AC22: 45566 | AD22: 45596
A23: SUB8902 | B23: CUS4610 | C23: Enterprise | D23: 9999 | E23: 45546 | F23: Active | H23: =IF(AND(E23 <= $M23, OR(G23 = "", G23 > $M23)), "Yes", "No") -> Yes | I23: =IF(AND(E23>=$M23,E23<=$M23),"Yes","No") -> No | J23: =IF(AND(G23<> " ",G23>=$L23,G23<=$M23),"Yes","No") -> No | K23: =MONTH(Table2[[#This Row],[Subscription Start]]) -> 9 | L23: =DATE(2024,Table2[[#This Row],[Month]],1) -> 45536 | M23: =DATE(2024,Table2[[#This Row],[Month]],30) -> 45565 | N23: =IF(Table2[[#This Row],[Active]]="Yes",1,0) -> 1 | O23: =IF(Table2[[#This Row],[Churned]]="Yes",1,0) -> 0 | P23: Sep
A24: SUB9169 | B24: CUS4125 | C24: Basic | D24: 999 | E24: 45546 | F24: Active | H24: =IF(AND(E24 <= $M24, OR(G24 = "", G24 > $M24)), "Yes", "No") -> Yes | I24: =IF(AND(E24>=$M24,E24<=$M24),"Yes","No") -> No | J24: =IF(AND(G24<> " ",G24>=$L24,G24<=$M24),"Yes","No") -> No | K24: =MONTH(Table2[[#This Row],[Subscription Start]]) -> 9 | L24: =DATE(2024,Table2[[#This Row],[Month]],1) -> 45536 | M24: =DATE(2024,Table2[[#This Row],[Month]],30) -> 45565 | N24: =IF(Table2[[#This Row],[Active]]="Yes",1,0) -> 1 | O24: =IF(Table2[[#This Row],[Churned]]="Yes",1,0) -> 0 | P24: Sep
A25: SUB8176 | B25: CUS4091 | C25: Basic | D25: 999 | E25: 45545 | F25: Active | H25: =IF(AND(E25 <= $M25, OR(G25 = "", G25 > $M25)), "Yes", "No") -> Yes | I25: =IF(AND(E25>=$M25,E25<=$M25),"Yes","No") -> No | J25: =IF(AND(G25<> " ",G25>=$L25,G25<=$M25),"Yes","No") -> No | K25: =MONTH(Table2[[#This Row],[Subscription Start]]) -> 9 | L25: =DATE(2024,Table2[[#This Row],[Month]],1) -> 45536 | M25: =DATE(2024,Table2[[#This Row],[Month]],30) -> 45565 | N25: =IF(Table2[[#This Row],[Active]]="Yes",1,0) -> 1 | O25: =IF(Table2[[#This Row],[Churned]]="Yes",1,0) -> 0 | P25: Sep
A26: SUB8793 | B26: CUS4286 | C26: Enterprise | D26: 9999 | E26: 45545 | F26: Active | H26: =IF(AND(E26 <= $M26, OR(G26 = "", G26 > $M26)), "Yes", "No") -> Yes | I26: =IF(AND(E26>=$M26,E26<=$M26),"Yes","No") -> No | J26: =IF(AND(G26<> " ",G26>=$L26,G26<=$M26),"Yes","No") -> No | K26: =MONTH(Table2[[#This Row],[Subscription Start]]) -> 9 | L26: =DATE(2024,Table2[[#This Row],[Month]],1) -> 45536 | M26: =DATE(2024,Table2[[#This Row],[Month]],30) -> 45565 | N26: =IF(Table2[[#This Row],[Active]]="Yes",1,0) -> 1 | O26: =IF(Table2[[#This Row],[Churned]]="Yes",1,0) -> 0 | P26: Sep
A27: SUB8958 | B27: CUS4724 | C27: Free | D27: 0 | E27: 45545 | F27: Canceled | G27: 45565 | H27: =IF(AND(E27 <= $M27, OR(G27 = "", G27 > $M27)), "Yes", "No") -> No | I27: =IF(AND(E27>=$M27,E27<=$M27),"Yes","No") -> No | J27: =IF(AND(G27<> " ",G27>=$L27,G27<=$M27),"Yes","No") -> Yes | K27: =MONTH(Table2[[#This Row],[Subscription Start]]) -> 9 | L27: =DATE(2024,Table2[[#This Row],[Month]],1) -> 45536 | M27: =DATE(2024,Table2[[#This Row],[Month]],30) -> 45565 | N27: =IF(Table2[[#This Row],[Active]]="Yes",1,0) -> 0 | O27: =IF(Table2[[#This Row],[Churned]]="Yes",1,0) -> 1 | P27: Sep
A28: SUB9115 | B28: CUS4621 | C28: Basic | D28: 999 | E28: 45545 | F28: Canceled | G28: 45565 | H28: =IF(AND(E28 <= $M28, OR(G28 = "", G28 > $M28)), "Yes", "No") -> No | I28: =IF(AND(E28>=$M28,E28<=$M28),"Yes","No") -> No | J28: =IF(AND(G28<> " ",G28>=$L28,G28<=$M28),"Yes","No") -> Yes | K28: =MONTH(Table2[[#This Row],[Subscription Start]]) -> 9 | L28: =DATE(2024,Table2[[#This Row],[Month]],1) -> 45536 | M28: =DATE(2024,Table2[[#This Row],[Month]],30) -> 45565 | N28: =IF(Table2[[#This Row],[Active]]="Yes",1,0) -> 0 | O28: =IF(Table2[[#This Row],[Churned]]="Yes",1,0) -> 1 | P28: Sep
A29: SUB8720 | B29: CUS4528 | C29: Free | D29: 0 | E29: 45544 | F29: Active | H29: =IF(AND(E29 <= $M29, OR(G29 = "", G29 > $M29)), "Yes", "No") -> Yes | I29: =IF(AND(E29>=$M29,E29<=$M29),"Yes","No") -> No | J29: =IF(AND(G29<> " ",G29>=$L29,G29<=$M29),"Yes","No") -> No | K29: =MONTH(Table2[[#This Row],[Subscription Start]]) -> 9 | L29: =DATE(2024,Table2[[#This Row],[Month]],1) -> 45536 | M29: =DATE(2024,Table2[[#This Row],[Month]],30) -> 45565 | N29: =IF(Table2[[#This Row],[Active]]="Yes",1,0) -> 1 | O29: =IF(Table2[[#This Row],[Churned]]="Yes",1,0) -> 0 | P29: Sep
A30: SUB9174 | B30: CUS4764 | C30: Pro | D30: 2499 | E30: 45544 | F30: Active | H30: =IF(AND(E30 <= $M30, OR(G30 = "", G30 > $M30)), "Yes", "No") -> Yes | I30: =IF(AND(E30>=$M30,E30<=$M30),"Yes","No") -> No | J30: =IF(AND(G30<> " ",G30>=$L30,G30<=$M30),"Yes","No") -> No | K30: =MONTH(Table2[[#This Row],[Subscription Start]]) -> 9 | L30: =DATE(2024,Table2[[#This Row],[Month]],1) -> 45536 | M30: =DATE(2024,Table2[[#This Row],[Month]],30) -> 45565 | N30: =IF(Table2[[#This Row],[Active]]="Yes",1,0) -> 1 | O30: =IF(Table2[[#This Row],[Churned]]="Yes",1,0) -> 0 | P30: Sep
A31: SUB8371 | B31: CUS4498 | C31: Free | D31: 0 | E31: 45543 | F31: Active | H31: =IF(AND(E31 <= $M31, OR(G31 = "", G31 > $M31)), "Yes", "No") -> Yes | I31: =IF(AND(E31>=$M31,E31<=$M31),"Yes","No") -> No | J31: =IF(AND(G31<> " ",G31>=$L31,G31<=$M31),"Yes","No") -> No | K31: =MONTH(Table2[[#This Row],[Subscription Start]]) -> 9 | L31: =DATE(2024,Table2[[#This Row],[Month]],1) -> 45536 | M31: =DATE(2024,Table2[[#This Row],[Month]],30) -> 45565 | N31: =IF(Table2[[#This Row],[Active]]="Yes",1,0) -> 1 | O31: =IF(Table2[[#This Row],[Churned]]="Yes",1,0) -> 0 | P31: Sep
A32: SUB8860 | B32: CUS4621 | C32: Pro | D32: 2499 | E32: 45543 | F32: Active | H32: =IF(AND(E32 <= $M32, OR(G32 = "", G32 > $M32)), "Yes", "No") -> Yes | I32: =IF(AND(E32>=$M32,E32<=$M32),"Yes","No") -> No | J32: =IF(AND(G32<> " ",G32>=$L32,G32<=$M32),"Yes","No") -> No | K32: =MONTH(Table2[[#This Row],[Subscription Start]]) -> 9 | L32: =DATE(2024,Table2[[#This Row],[Month]],1) -> 45536 | M32: =DATE(2024,Table2[[#This Row],[Month]],30) -> 45565 | N32: =IF(Table2[[#This Row],[Active]]="Yes",1,0) -> 1 | O32: =IF(Table2[[#This Row],[Churned]]="Yes",1,0) -> 0 | P32: Sep
A33: SUB8948 | B33: CUS4269 | C33: Basic | D33: 999 | E33: 45543 | F33: Active | H33: =IF(AND(E33 <= $M33, OR(G33 = "", G33 > $M33)), "Yes", "No") -> Yes | I33: =IF(AND(E33>=$M33,E33<=$M33),"Yes","No") -> No | J33: =IF(AND(G33<> " ",G33>=$L33,G33<=$M33),"Yes","No") -> No | K33: =MONTH(Table2[[#This Row],[Subscription Start]]) -> 9 | L33: =DATE(2024,Table2[[#This Row],[Month]],1) -> 45536 | M33: =DATE(2024,Table2[[#This Row],[Month]],30) -> 45565 | N33: =IF(Table2[[#This Row],[Active]]="Yes",1,0) -> 1 | O33: =IF(Table2[[#This Row],[Churned]]="Yes",1,0) -> 0 | P33: Sep
A34: SUB9155 | B34: CUS4230 | C34: Enterprise | D34: 9999 | E34: 45543 | F34: Active | H34: =IF(AND(E34 <= $M34, OR(G34 = "", G34 > $M34)), "Yes", "No") -> Yes | I34: =IF(AND(E34>=$M34,E34<=$M34),"Yes","No") -> No | J34: =IF(AND(G34<> " ",G34>=$L34,G34<=$M34),"Yes","No") -> No | K34: =MONTH(Table2[[#This Row],[Subscription Start]]) -> 9 | L34: =DATE(2024,Table2[[#This Row],[Month]],1) -> 45536 | M34: =DATE(2024,Table2[[#This Row],[Month]],30) -> 45565 | N34: =IF(Table2[[#This Row],[Active]]="Yes",1,0) -> 1 | O34: =IF(Table2[[#This Row],[Churned]]="Yes",1,0) -> 0 | P34: Sep
A35: SUB8278 | B35: CUS4137 | C35: Free | D35: 0 | E35: 45542 | F35: Active | H35: =IF(AND(E35 <= $M35, OR(G35 = "", G35 > $M35)), "Yes", "No") -> Yes | I35: =IF(AND(E35>=$M35,E35<=$M35),"Yes","No") -> No | J35: =IF(AND(G35<> " ",G35>=$L35,G35<=$M35),"Yes","No") -> No | K35: =MONTH(Table2[[#This Row],[Subscription Start]]) -> 9 | L35: =DATE(2024,Table2[[#This Row],[Month]],1) -> 45536 | M35: =DATE(2024,Table2[[#This Row],[Month]],30) -> 45565 | N35: =IF(Table2[[#This Row],[Active]]="Yes",1,0) -> 1 | O35: =IF(Table2[[#This Row],[Churned]]="Yes",1,0) -> 0 | P35: Sep
A36: SUB8090 | B36: CUS4206 | C36: Free | D36: 0 | E36: 45541 | F36: Active | H36: =IF(AND(E36 <= $M36, OR(G36 = "", G36 > $M36)), "Yes", "No") -> Yes | I36: =IF(AND(E36>=$M36,E36<=$M36),"Yes","No") -> No | J36: =IF(AND(G36<> " ",G36>=$L36,G36<=$M36),"Yes","No") -> No | K36: =MONTH(Table2[[#This Row],[Subscription Start]]) -> 9 | L36: =DATE(2024,Table2[[#This Row],[Month]],1) -> 45536 | M36: =DATE(2024,Table2[[#This Row],[Month]],30) -> 45565 | N36: =IF(Table2[[#This Row],[Active]]="Yes",1,0) -> 1 | O36: =IF(Table2[[#This Row],[Churned]]="Yes",1,0) -> 0 | P36: Sep
A37: SUB8128 | B37: CUS4530 | C37: Free | D37: 0 | E37: 45541 | F37: Canceled | G37: 45565 | H37: =IF(AND(E37 <= $M37, OR(G37 = "", G37 > $M37)), "Yes", "No") -> No | I37: =IF(AND(E37>=$M37,E37<=$M37),"Yes","No") -> No | J37: =IF(AND(G37<> " ",G37>=$L37,G37<=$M37),"Yes","No") -> Yes | K37: =MONTH(Table2[[#This Row],[Subscription Start]]) -> 9 | L37: =DATE(2024,Table2[[#This Row],[Month]],1) -> 45536 | M37: =DATE(2024,Table2[[#This Row],[Month]],30) -> 45565 | N37: =IF(Table2[[#This Row],[Active]]="Yes",1,0) -> 0 | O37: =IF(Table2[[#This Row],[Churned]]="Yes",1,0) -> 1 | P37: Sep
A38: SUB8364 | B38: CUS4439 | C38: Free | D38: 0 | E38: 45540 | F38: Canceled | G38: 45565 | H38: =IF(AND(E38 <= $M38, OR(G38 = "", G38 > $M38)), "Yes", "No") -> No | I38: =IF(AND(E38>=$M38,E38<=$M38),"Yes","No") -> No | J38: =IF(AND(G38<> " ",G38>=$L38,G38<=$M38),"Yes","No") -> Yes | K38: =MONTH(Table2[[#This Row],[Subscription Start]]) -> 9 | L38: =DATE(2024,Table2[[#This Row],[Month]],1) -> 45536 | M38: =DATE(2024,Table2[[#This Row],[Month]],30) -> 45565 | N38: =IF(Table2[[#This Row],[Active]]="Yes",1,0) -> 0 | O38: =IF(Table2[[#This Row],[Churned]]="Yes",1,0) -> 1 | P38: Sep
A39: SUB8454 | B39: CUS4394 | C39: Pro | D39: 2499 | E39: 45540 | F39: Canceled | G39: 45565 | H39: =IF(AND(E39 <= $M39, OR(G39 = "", G39 > $M39)), "Yes", "No") -> No | I39: =IF(AND(E39>=$M39,E39<=$M39),"Yes","No") -> No | J39: =IF(AND(G39<> " ",G39>=$L39,G39<=$M39),"Yes","No") -> Yes | K39: =MONTH(Table2[[#This Row],[Subscription Start]]) -> 9 | L39: =DATE(2024,Table2[[#This Row],[Month]],1) -> 45536 | M39: =DATE(2024,Table2[[#This Row],[Month]],30) -> 45565 | N39: =IF(Table2[[#This Row],[Active]]="Yes",1,0) -> 0 | O39: =IF(Table2[[#This Row],[Churned]]="Yes",1,0) -> 1 | P39: Sep
A40: SUB8824 | B40: CUS4058 | C40: Free | D40: 0 | E40: 45540 | F40: Active | H40: =IF(AND(E40 <= $M40, OR(G40 = "", G40 > $M40)), "Yes", "No") -> Yes | I40: =IF(AND(E40>=$M40,E40<=$M40),"Yes","No") -> No | J40: =IF(AND(G40<> " ",G40>=$L40,G40<=$M40),"Yes","No") -> No | K40: =MONTH(Table2[[#This Row],[Subscription Start]]) -> 9 | L40: =DATE(2024,Table2[[#This Row],[Month]],1) -> 45536 | M40: =DATE(2024,Table2[[#This Row],[Month]],30) -> 45565 | N40: =IF(Table2[[#This Row],[Active]]="Yes",1,0) -> 1 | O40: =IF(Table2[[#This Row],[Churned]]="Yes",1,0) -> 0 | P40: Sep
...

Sheet Users
A1: Customer ID | B1: Signup Date | C1: Country | D1: Acquisition Source | E1: Company Size
A2: CUS4000 | B2: 45474 | C2: UK | D2: Google Ads | E2: 21-100
A3: CUS4001 | B3: 45476 | C3: India | D3: Google Ads | E3: 1-5
A4: CUS4002 | B4: 45389 | C4: US | D4: Google Ads | E4: 100+
A5: CUS4003 | B5: 45478 | C5: India | D5: Direct | E5: 6-20
A6: CUS4004 | B6: 45429 | C6: Canada | D6: Google Ads | E6: 1-5
A7: CUS4005 | B7: 45426 | C7: India | D7: LinkedIn | E7: 1-5
A8: CUS4006 | B8: 45325 | C8: India | D8: Referral | E8: 1-5
A9: CUS4007 | B9: 45507 | C9: Germany | D9: Google Ads | E9: 1-5
A10: CUS4008 | B10: 45492 | C10: Germany | D10: Google Ads | E10: 6-20
A11: CUS4009 | B11: 45354 | C11: India | D11: Content | E11: 6-20
A12: CUS4010 | B12: 45340 | C12: India | D12: Direct | E12: 21-100
A13: CUS4011 | B13: 45443 | C13: Canada | D13: Google Ads | E13: 6-20
... A801: CUS4799 | B801: 45304 | C801: US | D801: LinkedIn | E801: 6-20

Sheet Subscription+Users
A1: Subscription ID | B1: Customer ID | C1: Plan Type | D1: Monthly Price | E1: Subscription Start | F1: Subscription Status | G1: Churn Date | H1: Signup Date | I1: Country | J1: Acquisition Source | K1: Company Size
A2: SUB8000 | B2: CUS4797 | C2: Free | D2: 0 | E2: 45399 | F2: Active | H2: 45390 | I2: India | J2: Google Ads | K2: 1-5
A3: SUB8052 | B3: CUS4797 | C3: Basic | D3: 999 | E3: 45411 | F3: Active | H3: 45390 | I3: India | J3: Google Ads | K3: 1-5
A4: SUB8476 | B4: CUS4797 | C4: Free | D4: 0 | E4: 45412 | F4: Active | H4: 45390 | I4: India | J4: Google Ads | K4: 1-5
A5: SUB8618 | B5: CUS4797 | C5: Basic | D5: 999 | E5: 45413 | F5: Active | H5: 45390 | I5: India | J5: Google Ads | K5: 1-5
A6: SUB8657 | B6: CUS4000 | C6: Free | D6: 0 | E6: 45492 | F6: Active | H6: 45474 | I6: UK | J6: Google Ads | K6: 21-100
A7: SUB8001 | B7: CUS4470 | C7: Free | D7: 0 | E7: 45489 | F7: Canceled | G7: 45565 | H7: 45483 | I7: Canada | J7: Content | K7: 6-20
A8: SUB8002 | B8: CUS4378 | C8: Free | D8: 0 | E8: 45492 | F8: Canceled | G8: 45565 | H8: 45484 | I8: UK | J8: Content | K8: 100+
A9: SUB8139 | B9: CUS4002 | C9: Pro | D9: 2499 | E9: 45419 | F9: Active | H9: 45389 | I9: US | J9: Google Ads | K9: 100+
A10: SUB8266 | B10: CUS4002 | C10: Basic | D10: 999 | E10: 45407 | F10: Active | H10: 45389 | I10: US | J10: Google Ads | K10: 100+
A11: SUB8694 | B11: CUS4002 | C11: Basic | D11: 999 | E11: 45417 | F11: Canceled | G11: 45465 | H11: 45389 | I11: US | J11: Google Ads | K11: 100+
A12: SUB8003 | B12: CUS4626 | C12: Basic | D12: 999 | E12: 45515 | F12: Active | H12: 45515 | I12: India | J12: Content | K12: 6-20
A13: SUB8320 | B13: CUS4626 | C13: Pro | D13: 2499 | E13: 45515 | F13: Active | H13: 45515 | I13: India | J13: Content | K13: 6-20
A14: SUB8004 | B14: CUS4128 | C14: Pro | D14: 2499 | E14: 45533 | F14: Active | H14: 45531 | I14: India | J14: LinkedIn | K14: 1-5
A15: SUB8169 | B15: CUS4128 | C15: Free | D15: 0 | E15: 45535 | F15: Active | H15: 45531 | I15: India | J15: LinkedIn | K15: 1-5
A16: SUB8721 | B16: CUS4128 | C16: Free | D16: 0 | E16: 45534 | F16: Canceled | G16: 45565 | H16: 45531 | I16: India | J16: LinkedIn | K16: 1-5
A17: SUB8005 | B17: CUS4019 | C17: Basic | D17: 999 | E17: 45334 | F17: Active | H17: 45320 | I17: India | J17: LinkedIn | K17: 21-100
A18: SUB8186 | B18: CUS4019 | C18: Basic | D18: 999 | E18: 45330 | F18: Active | H18: 45320 | I18: India | J18: LinkedIn | K18: 21-100
A19: SUB8467 | B19: CUS4019 | C19: Free | D19: 0 | E19: 45334 | F19: Active | H19: 45320 | I19: India | J19: LinkedIn | K19: 21-100
A20: SUB8521 | B20: CUS4019 | C20: Basic | D20: 999 | E20: 45349 | F20: Active | H20: 45320 | I20: India | J20: LinkedIn | K20: 21-100
A21: SUB8066 | B21: CUS4005 | C21: Enterprise | D21: 9999 | E21: 45430 | F21: Active | H21: 45426 | I21: India | J21: LinkedIn | K21: 1-5
A22: SUB8006 | B22: CUS4752 | C22: Free | D22: 0 | E22: 45418 | F22: Active | H22: 45410 | I22: Canada | J22: Content | K22: 1-5
A23: SUB8619 | B23: CUS4752 | C23: Free | D23: 0 | E23: 45437 | F23: Active | H23: 45410 | I23: Canada | J23: Content | K23: 1-5
A24: SUB8293 | B24: CUS4006 | C24: Enterprise | D24: 9999 | E24: 45325 | F24: Canceled | G24: 45441 | H24: 45325 | I24: India | J24: Referral | K24: 1-5
A25: SUB8007 | B25: CUS4103 | C25: Basic | D25: 999 | E25: 45486 | F25: Active | H25: 45471 | I25: India | J25: Direct | K25: 1-5
A26: SUB8034 | B26: CUS4103 | C26: Basic | D26: 999 | E26: 45471 | F26: Canceled | G26: 45565 | H26: 45471 | I26: India | J26: Direct | K26: 1-5
A27: SUB8710 | B27: CUS4103 | C27: Basic | D27: 999 | E27: 45501 | F27: Active | H27: 45471 | I27: India | J27: Direct | K27: 1-5
A28: SUB8724 | B28: CUS4103 | C28: Basic | D28: 999 | E28: 45472 | F28: Active | H28: 45471 | I28: India | J28: Direct | K28: 1-5
A29: SUB8781 | B29: CUS4007 | C29: Pro | D29: 2499 | E29: 45531 | F29: Active | H29: 45507 | I29: Germany | J29: Google Ads | K29: 1-5
A30: SUB8008 | B30: CUS4044 | C30: Basic | D30: 999 | E30: 45393 | F30: Active | H30: 45390 | I30: Canada | J30: LinkedIn | K30: 1-5
A31: SUB8009 | B31: CUS4546 | C31: Basic | D31: 999 | E31: 45387 | F31: Canceled | G31: 45565 | H31: 45383 | I31: Canada | J31: Referral | K31: 1-5
A32: SUB8083 | B32: CUS4546 | C32: Basic | D32: 999 | E32: 45385 | F32: Canceled | G32: 45475 | H32: 45383 | I32: Canada | J32: Referral | K32: 1-5
A33: SUB8174 | B33: CUS4009 | C33: Basic | D33: 999 | E33: 45384 | F33: Active | H33: 45354 | I33: India | J33: Content | K33: 6-20
A34: SUB8731 | B34: CUS4009 | C34: Basic | D34: 999 | E34: 45381 | F34: Canceled | G34: 45565 | H34: 45354 | I34: India | J34: Content | K34: 6-20
A35: SUB8771 | B35: CUS4009 | C35: Free | D35: 0 | E35: 45361 | F35: Active | H35: 45354 | I35: India | J35: Content | K35: 6-20
A36: SUB8010 | B36: CUS4200 | C36: Pro | D36: 2499 | E36: 45399 | F36: Active | H36: 45379 | I36: India | J36: Content | K36: 6-20
A37: SUB8064 | B37: CUS4200 | C37: Basic | D37: 999 | E37: 45385 | F37: Active | H37: 45379 | I37: India | J37: Content | K37: 6-20
A38: SUB8158 | B38: CUS4200 | C38: Pro | D38: 2499 | E38: 45385 | F38: Active | H38: 45379 | I38: India | J38: Content | K38: 6-20
A39: SUB8411 | B39: CUS4010 | C39: Pro | D39: 2499 | E39: 45342 | F39: Active | H39: 45340 | I39: India | J39: Direct | K39: 21-100
A40: SUB8011 | B40: CUS4023 | C40: Free | D40: 0 | E40: 45464 | F40: Canceled | G40: 45524 | H40: 45450 | I40: Canada | J40: Google Ads | K40: 21-100
...

Sheet Subscription+Charges
A1: charge_id | B1: subscription_id | C1: customer_id | D1: charge_date | E1: amount | F1: status | G1: payment_method | H1: Plan Type | I1: Monthly Price | J1: Subcription Start | K1: Subscription Status | L1: Churn Date | M1: Signup Date | N1: Country | O1: Acquisition Source | P1: Company Size
A2: CHG95000 | B2: SUB8003 | C2: CUS4626 | D2: 45505 | E2: 999 | F2: Paid | G2: Card | H2: Basic | I2: 999 | J2: 45515 | K2: Active | M2: 45515 | N2: India | O2: Content | P2: 6-20
A3: CHG95001 | B3: SUB8003 | C3: CUS4626 | D3: 45536 | E3: 999 | F3: Paid | G3: Card | H3: Basic | I3: 999 | J3: 45515 | K3: Active | M3: 45515 | N3: India | O3: Content | P3: 6-20
A4: CHG95150 | B4: SUB8052 | C4: CUS4797 | D4: 45386 | E4: 999 | F4: Paid | G4: Card | H4: Basic | I4: 999 | J4: 45411 | K4: Active | M4: 45390 | N4: India | O4: Google Ads | P4: 1-5
A5: CHG95151 | B5: SUB8052 | C5: CUS4797 | D5: 45415 | E5: 999 | F5: Paid | G5: Card | H5: Basic | I5: 999 | J5: 45411 | K5: Active | M5: 45390 | N5: India | O5: Google Ads | P5: 1-5
A6: CHG95152 | B6: SUB8052 | C6: CUS4797 | D6: 45447 | E6: 999 | F6: Paid | G6: Card | H6: Basic | I6: 999 | J6: 45411 | K6: Active | M6: 45390 | N6: India | O6: Google Ads | P6: 1-5
A7: CHG95153 | B7: SUB8052 | C7: CUS4797 | D7: 45475 | E7: 999 | F7: Paid | G7: Card | H7: Basic | I7: 999 | J7: 45411 | K7: Active | M7: 45390 | N7: India | O7: Google Ads | P7: 1-5
A8: CHG95154 | B8: SUB8052 | C8: CUS4797 | D8: 45507 | E8: 999 | F8: Paid | G8: UPI | H8: Basic | I8: 999 | J8: 45411 | K8: Active | M8: 45390 | N8: India | O8: Google Ads | P8: 1-5
A9: CHG95155 | B9: SUB8052 | C9: CUS4797 | D9: 45539 | E9: 999 | F9: Paid | G9: Card | H9: Basic | I9: 999 | J9: 45411 | K9: Active | M9: 45390 | N9: India | O9: Google Ads | P9: 1-5
A10: CHG95002 | B10: SUB8004 | C10: CUS4128 | D10: 45507 | E10: 2499 | F10: Paid | G10: Card | H10: Pro | I10: 2499 | J10: 45533 | K10: Active | M10: 45531 | N10: India | O10: LinkedIn | P10: 1-5
A11: CHG95003 | B11: SUB8004 | C11: CUS4128 | D11: 45539 | E11: 2499 | F11: Paid | G11: Card | H11: Pro | I11: 2499 | J11: 45533 | K11: Active | M11: 45531 | N11: India | O11: LinkedIn | P11: 1-5
A12: CHG95004 | B12: SUB8005 | C12: CUS4019 | D12: 45326 | E12: 999 | F12: Paid | G12: Card | H12: Basic | I12: 999 | J12: 45334 | K12: Active | M12: 45320 | N12: India | O12: LinkedIn | P12: 21-100
A13: CHG95005 | B13: SUB8005 | C13: CUS4019 | D13: 45353 | E13: 999 | F13: Paid | G13: Card | H13: Basic | I13: 999 | J13: 45334 | K13: Active | M13: 45320 | N13: India | O13: LinkedIn | P13: 21-100
... A54: CHG95193 | B54: SUB8066 | C54: CUS4005 | D54: 45538 | E54: 9999 | F54: Paid | G54: Card | H54: Enterprise | I54: 9999 | J54: 45430 | K54: Active | M54: 45426 | N54: India | O54: LinkedIn | P54: 1-5
A55: CHG95021 | B55: SUB8009 | C55: CUS4546 | D55: 45383 | E55: 999 | F55: Paid | G55: Card | H55: Basic | I55: 999 | J55: 45387 | K55: Canceled | L55: 45565 | M55: 45383 | N55: Canada | O55: Referral | P55: 1-5
A56: CHG95022 | B56: SUB8009 | C56: CUS4546 | D56: 45415 | E56: 999 | F56: Paid | G56: Card | H56: Basic | I56: 999 | J56: 45387 | K56: Canceled | L56: 45565 | M56: 45383 | N56: Canada | O56: Referral | P56: 1-5
A57: CHG95023 | B57: SUB8009 | C57: CUS4546 | D57: 45445 | E57: 999 | F57: Paid | G57: Card | H57: Basic | I57: 999 | J57: 45387 | K57: Canceled | L57: 45565 | M57: 45383 | N57: Canada | O57: Referral | P57: 1-5
A58: CHG95024 | B58: SUB8009 | C58: CUS4546 | D58: 45474 | E58: 999 | F58: Paid | G58: UPI | H58: Basic | I58: 999 | J58: 45387 | K58: Canceled | L58: 45565 | M58: 45383 | N58: Canada | O58: Referral | P58: 1-5
A59: CHG95025 | B59: SUB8009 | C59: CUS4546 | D59: 45505 | E59: 999 | F59: Paid | G59: Card | H59: Basic | I59: 999 | J59: 45387 | K59: Canceled | L59: 45565 | M59: 45383 | N59: Canada | O59: Referral | P59: 1-5
A60: CHG95026 | B60: SUB8009 | C60: CUS4546 | D60: 45538 | E60: 999 | F60: Paid | G60: PayPal | H60: Basic | I60: 999 | J60: 45387 | K60: Canceled | L60: 45565 | M60: 45383 | N60: Canada | O60: Referral | P60: 1-5
A61: CHG96000 | B61: SUB8293 | C61: CUS4006 | D61: 45323 | E61: 9999 | F61: Paid | G61: PayPal | H61: Enterprise | I61: 9999 | J61: 45325 | K61: Canceled | L61: 45441 | M61: 45325 | N61: India | O61: Referral | P61: 1-5
A62: CHG96001 | B62: SUB8293 | C62: CUS4006 | D62: 45352 | E62: 9999 | F62: Paid | G62: Card | H62: Enterprise | I62: 9999 | J62: 45325 | K62: Canceled | L62: 45441 | M62: 45325 | N62: India | O62: Referral | P62: 1-5
A63: CHG96002 | B63: SUB8293 | C63: CUS4006 | D63: 45385 | E63: 9999 | F63: Paid | G63: Card | H63: Enterprise | I63: 9999 | J63: 45325 | K63: Canceled | L63: 45441 | M63: 45325 | N63: India | O63: Referral | P63: 1-5
A64: CHG96003 | B64: SUB8293 | C64: CUS4006 | D64: 45415 | E64: 9999 | F64: Paid | G64: Card | H64: Enterprise | I64: 9999 | J64: 45325 | K64: Canceled | L64: 45441 | M64: 45325 | N64: India | O64: Referral | P64: 1-5
A65: CHG95086 | B65: SUB8034 | C65: CUS4103 | D65: 45446 | E65: 999 | F65: Paid | G65: Card | H65: Basic | I65: 999 | J65: 45471 | K65: Canceled | L65: 45565 | M65: 45471 | N65: India | O65: Direct | P65: 1-5
A66: CHG95087 | B66: SUB8034 | C66: CUS4103 | D66: 45474 | E66: 999 | F66: Paid | G66: Card | H66: Basic | I66: 999 | J66: 45471 | K66: Canceled | L66: 45565 | M66: 45471 | N66: India | O66: Direct | P66: 1-5
... A68: CHG95089 | B68: SUB8034 | C68: CUS4103 | D68: 45539 | E68: 999 | F68: Paid | G68: UPI | H68: Basic | I68: 999 | J68: 45471 | K68: Canceled | L68: 45565 | M68: 45471 | N68: India | O68: Direct | P68: 1-5
A69: CHG95027 | B69: SUB8010 | C69: CUS4200 | D69: 45385 | E69: 2499 | F69: Paid | G69: Card | H69: Pro | I69: 2499 | J69: 45399 | K69: Active | M69: 45379 | N69: India | O69: Content | P69: 6-20
A70: CHG95028 | B70: SUB8010 | C70: CUS4200 | D70: 45413 | E70: 2499 | F70: Paid | G70: Card | H70: Pro | I70: 2499 | J70: 45399 | K70: Active | M70: 45379 | N70: India | O70: Content | P70: 6-20
A71: CHG95029 | B71: SUB8010 | C71: CUS4200 | D71: 45445 | E71: 2499 | F71: Paid | G71: Card | H71: Pro | I71: 2499 | J71: 45399 | K71: Active | M71: 45379 | N71: India | O71: Content | P71: 6-20
A72: CHG95030 | B72: SUB8010 | C72: CUS4200 | D72: 45475 | E72: 2499 | F72: Paid | G72: PayPal | H72: Pro | I72: 2499 | J72: 45399 | K72: Active | M72: 45379 | N72: India | O72: Content | P72: 6-20
A73: CHG95031 | B73: SUB8010 | C73: CUS4200 | D73: 45506 | E73: 2499 | F73: Paid | G73: PayPal | H73: Pro | I73: 2499 | J73: 45399 | K73: Active | M73: 45379 | N73: India | O73: Content | P73: 6-20
A74: CHG95032 | B74: SUB8010 | C74: CUS4200 | D74: 45537 | E74: 2499 | F74: Paid | G74: Card | H74: Pro | I74: 2499 | J74: 45399 | K74: Active | M74: 45379 | N74: India | O74: Content | P74: 6-20
A75: CHG95275 | B75: SUB8083 | C75: CUS4546 | D75: 45383 | E75: 999 | F75: Paid | G75: Card | H75: Basic | I75: 999 | J75: 45385 | K75: Canceled | L75: 45475 | M75: 45383 | N75: Canada | O75: Referral | P75: 1-5
A76: CHG95276 | B76: SUB8083 | C76: CUS4546 | D76: 45413 | E76: 999 | F76: Paid | G76: Wire | H76: Basic | I76: 999 | J76: 45385 | K76: Canceled | L76: 45475 | M76: 45383 | N76: Canada | O76: Referral | P76: 1-5
A77: CHG95277 | B77: SUB8083 | C77: CUS4546 | D77: 45445 | E77: 999 | F77: Paid | G77: Card | H77: Basic | I77: 999 | J77: 45385 | K77: Canceled | L77: 45475 | M77: 45383 | N77: Canada | O77: Referral | P77: 1-5
A78: CHG95278 | B78: SUB8083 | C78: CUS4546 | D78: 45475 | E78: 999 | F78: Paid | G78: UPI | H78: Basic | I78: 999 | J78: 45385 | K78: Canceled | L78: 45475 | M78: 45383 | N78: Canada | O78: Referral | P78: 1-5
A79: CHG95607 | B79: SUB8174 | C79: CUS4009 | D79: 45384 | E79: 999 | F79: Paid | G79: Card | H79: Basic | I79: 999 | J79: 45384 | K79: Active | M79: 45354 | N79: India | O79: Content | P79: 6-20
A80: CHG95608 | B80: SUB8174 | C80: CUS4009 | D80: 45414 | E80: 999 | F80: Paid | G80: Card | H80: Basic | I80: 999 | J80: 45384 | K80: Active | M80: 45354 | N80: India | O80: Content | P80: 6-20
A81: CHG95609 | B81: SUB8174 | C81: CUS4009 | D81: 45446 | E81: 999 | F81: Paid | G81: Card | H81: Basic | I81: 999 | J81: 45384 | K81: Active | M81: 45354 | N81: India | O81: Content | P81: 6-20
...

Sheet Calendar
A1: Month | B1: Start | C1: End
A2: 45292 | B2: 45292 | C2: 45322
A3: 45323 | B3: 45323 | C3: 45351
A4: 45352 | B4: 45717 | C4: 45382
A5: 45383 | B5: 45383 | C5: 45412
A6: 45413 | B6: 45413 | C6: 45443
A7: 45444 | B7: 45444 | C7: 45473
A8: 45474 | B8: 45474 | C8: 45504
A9: 45505 | B9: 45505 | C9: 45535
A10: 45536 | B10: 45536 | C10: 45565
A11: 45566 | B11: 45566 | C11: 45596

Sheet Cal Table
A1: KPI | B1: Jan | C1: Feb | D1: Mar | E1: Apr | F1: May | G1: June | H1: July | I1: August | J1: September
A2: MRR | B2: =SUMIF(Subscription!H1124:H1201,"Yes",Subscription!D1124:D1201) -> 94947 | C2: =SUMIF(Subscription!H1007:H1123,"Yes",Subscription!D1007:D1123) -> 155418 | D2: =SUMIF(Subscription!H840:H1006,"Yes",Subscription!D840:D1006) -> 220386 | E2: =SUMIF(Subscription!H685:H839,"Yes",Subscription!D685:D839) -> 187392 | F2: =SUMIF(Subscription!H525:H684,"Yes",Subscription!D525:D684) -> 284388 | G2: =SUMIF(Subscription!H367:H542,"Yes",Subscription!D367:D542) -> 240387 | H2: =SUMIF(Subscription!H232:H366,"Yes",Subscription!D232:D366) -> 175410 | I2: =SUMIF(Subscription!H64:H231,"Yes",Subscription!D64:D231) -> 269868 | J2: =SUMIF(Subscription!H2:H63,"Yes",Subscription!D2:D63) -> 72969
A3: ARR | B3: =B2*12 -> 1139364 | C3: =C2*12 -> 1865016 | D3: =D2*12 -> 2644632 | E3: =E2*12 -> 2248704 | F3: =F2*12 -> 3412656 | G3: =G2*12 -> 2884644 | H3: =H2*12 -> 2104920 | I3: =I2*12 -> 3238416 | J3: =J2*12 -> 875628
A4: New MRR | B4: =SUMIF(Subscription!I1124:I1201,"Yes",Subscription!D1124:D1201) -> 14994 | C4: =SUMIF(Subscription!I1007:I1123,"Yes",Subscription!D1007:D1123) -> 4998 | D4: =SUMIF(Subscription!I840:I1006,"Yes",Subscription!D840:D1006) -> 6996 | E4: =SUMIF(Subscription!I685:I839,"Yes",Subscription!D685:D839) -> 12492 | F4: =SUMIF(Subscription!I525:I684,"Yes",Subscription!D525:D684) -> 19998 | G4: =SUMIF(Subscription!I367:I542,"Yes",Subscription!D367:D542) -> 20997 | H4: =SUMIF(Subscription!I232:I366,"Yes",Subscription!D232:D366) -> 5997 | I4: =SUMIF(Subscription!I64:I231,"Yes",Subscription!D64:D231) -> 16992 | J4: =SUMIF(Subscription!I2:I63,"Yes",Subscription!D2:D63) -> 0
A5: Churned MRR | B5: =SUMIF(Subscription!J1124:J1201,"Yes",Subscription!D1124:D1201) -> 0 | C5: =SUMIF(Subscription!K1124:K1201,"Yes",Subscription!E1124:E1201) -> 0 | D5: =SUMIF(Subscription!L1124:L1201,"Yes",Subscription!F1124:F1201) -> 0 | E5: =SUMIF(Subscription!M1124:M1201,"Yes",Subscription!G1124:G1201) -> 0 | F5: =SUMIF(Subscription!N1124:N1201,"Yes",Subscription!H1124:H1201) -> 0 | G5: =SUMIF(Subscription!O1124:O1201,"Yes",Subscription!I1124:I1201) -> 0 | H5: =SUMIF(Subscription!P1124:P1201,"Yes",Subscription!J1124:J1201) -> 0 | I5: =SUMIF(Subscription!Q1124:Q1201,"Yes",Subscription!K1124:K1201) -> 0 | J5: =SUMIF(Subscription!J2:J63,"Yes",Subscription!D2:D63) -> 24990
A6: Net New MRR | B6: =B4-0 -> 14994 | C6: =C4-0 -> 4998 | D6: =D4-0 -> 6996 | E6: =E4-0 -> 12492 | F6: =F4-0 -> 19998 | G6: =G4-0 -> 20997 | H6: =H4-0 -> 5997 | I6: =I4-0 -> 16992 | J6: -24990
A7: Active Customer | B7: =COUNTIF(Subscription!N1124:N1201,1) -> 78 | C7: =COUNTIF(Subscription!N1007:N1123,1) -> 117 | D7: =COUNTIF(Subscription!N840:N1006,1) -> 167 | E7: =COUNTIF(Subscription!N685:N839,1) -> 155 | F7: =COUNTIF(Subscription!N525:N684,1) -> 158 | G7: =COUNTIF(Subscription!N367:N524,1) -> 158 | H7: =COUNTIF(Subscription!N232:N366,1) -> 135 | I7: =COUNTIF(Subscription!N64:N231,1) -> 168 | J7: =COUNTIF(Subscription!N2:N63,1) -> 48
A8: Churn Rate | B8: =COUNTIF(Subscription!O1124:O1201,1)/'Cal Table'!B7 -> 0 | C8: =COUNTIF(Subscription!P1124:P1201,1)/'Cal Table'!C7 -> 0 | D8: =COUNTIF(Subscription!Q1124:Q1201,1)/'Cal Table'!D7 -> 0 | E8: =COUNTIF(Subscription!R1124:R1201,1)/'Cal Table'!E7 -> 0 | F8: =COUNTIF(Subscription!S1124:S1201,1)/'Cal Table'!F7 -> 0 | G8: =COUNTIF(Subscription!T1124:T1201,1)/'Cal Table'!G7 -> 0 | H8: =COUNTIF(Subscription!U1124:U1201,1)/'Cal Table'!H7 -> 0 | I8: =COUNTIF(Subscription!V1124:V1201,1)/'Cal Table'!I7 -> 0 | J8: =COUNTIF(Subscription!O2:O63,1)/'Cal Table'!J7 -> 0.29166667
A9: ARPU | B9: =B2/B7 -> 1217.2692 | C9: =C2/C7 -> 1328.359 | D9: =D2/D7 -> 1319.6766 | E9: =E2/E7 -> 1208.9806 | F9: =F2/F7 -> 1799.9241 | G9: =G2/G7 -> 1521.4367 | H9: =H2/H7 -> 1299.3333 | I9: =I2/I7 -> 1606.3571 | J9: =J2/J7 -> 1520.1875
A12: Month | B12: MRR | C12: Active Customer | D12: ARPU | E12: Month NO. | F12: ARR | G12: Churn Rate
A13: Mar | B13: 220386 | C13: 167 | D13: 1319.98 | E13: 3 | F13: 2644632 | G13: 0
A14: Apr | B14: 187392 | C14: 155 | D14: 1208.98 | E14: 4 | F14: 2248704 | G14: 0
A15: May | B15: 284388 | C15: 158 | D15: 1799.92 | E15: 5 | F15: 3412656 | G15: 0
A16: Aug | B16: 269868 | C16: 168 | D16: 1606.36 | E16: 8 | F16: 3238416 | G16: 0
A17: Sep | B17: 72969 | C17: 48 | D17: 1520.19 | E17: 9 | F17: 875628 | G17: 0.29
A18: Feb | B18: 155418 | C18: 117 | D18: 1328.68 | E18: 2 | F18: 1865016 | G18: 0
A19: Jan | B19: 94947 | C19: 78 | D19: 1217.27 | E19: 1 | F19: 113364 | G19: 0
A20: July | B20: 175410 | C20: 135 | D20: 1299.33 | E20: 7 | F20: 2104920 | G20: 0
A21: June | B21: 240387 | C21: 158 | D21: 1521.44 | E21: 6 | F21: 2884644 | G21: 0

Sheet CARD
A1: Row Labels | B1: Sum of MRR
A2: Jan | B2: 94947 | F2: =B2 -> 94947
A3: Feb | B3: 155418
A4: Mar | B4: 220386 | D4: 94947
A5: Apr | B5: 187392
A6: May | B6: 284388
A7: Aug | B7: 269868
A8: Sep | B8: 72969
A9: July | B9: 175410
A10: June | B10: 240387
A11: Grand Total | B11: 1701165
A14: Row Labels | B14: Sum of MRR
A15: Apr | B15: 187392
A16: Aug | B16: 269868
A17: Feb | B17: 155418
A18: Jan | B18: 94947
A19: July | B19: 175410
A20: June | B20: 240387
A21: Mar | B21: 220386
A22: May | B22: 284388
A23: Sep | B23: 72969
A24: Grand Total | B24: 1701165
A27: Row Labels | B27: Sum of MRR
A28: 1
A29: Jan | B29: 94947
A30: 2
A31: Feb | B31: 155418
A32: 3
A33: Mar | B33: 220386
A34: 4
A35: Apr | B35: 187392
A36: 5
A37: May | B37: 284388
A38: 6
A39: Jun | B39: 240387
A40: 7
A41: Jul | B41: 175410
A42: 8
A43: Aug | B43: 269868
A44: 9
...

Sheet KPI Table
A3: Month | B3: ARR | C3: MRR | D3: New MRR | E3: Churned MRR | F3: Net MRR | G3: Active Customer | H3: Churn Rate | I3: ARPU | J3: Month Num
A4: Jan | B4: 113364 | C4: 94947 | D4: 14994 | E4: 0 | G4: 78 | H4: 0 | I4: 1217.27 | J4: 1
A5: Feb | B5: 1865016 | C5: 155418 | D5: 4998 | E5: 0 | G5: 117 | H5: 0 | I5: 1328.68 | J5: 2
A6: Mar | B6: 2644632 | C6: 220386 | D6: 6996 | E6: 0 | G6: 167 | H6: 0 | I6: 1319.98 | J6: 3
A7: Apr | B7: 2248704 | C7: 187392 | D7: 12492 | E7: 0 | G7: 155 | H7: 0 | I7: 1208.98 | J7: 4
A8: May | B8: 3412656 | C8: 284388 | D8: 19998 | E8: 0 | G8: 158 | H8: 0 | I8: 1799.92 | J8: 5
A9: Jun | B9: 2884644 | C9: 240387 | D9: 20997 | E9: 0 | G9: 158 | H9: 0 | I9: 1521.44 | J9: 6
A10: Jul | B10: 2104920 | C10: 175410 | D10: 5997 | E10: 0 | G10: 135 | H10: 0 | I10: 1299.33 | J10: 7
A11: Aug | B11: 3238416 | C11: 269868 | D11: 16992 | E11: 0 | G11: 168 | H11: 0 | I11: 1606.36 | J11: 8
A12: Sep | B12: 875628 | C12: 72969 | D12: 0 | E12: 24990 | G12: 48 | H12: 0.29 | I12: 1520.19 | J12: 9
G20: =B4 -> 113364
D21: =C6 -> 220386

Sheet MRR Trend
A1: Active | B1: Yes
A3: Row Labels | B3: Sum of Monthly Price
A4: Jan | B4: 94947
A5: Feb | B5: 155418
A6: Mar | B6: 220386
A7: Apr | B7: 187392
A8: May | B8: 284388
A9: Jun | B9: 212895
A10: Jul | B10: 175410
A11: Aug | B11: 269868
A12: Sep | B12: 72969
A13: Grand Total | B13: 1673673

Sheet Active vs Cancelled
A3: Count of Subscription ID | B3: Column Labels
A4: Row Labels | B4: Basic | C4: Enterprise | D4: Free | E4: Pro
A5: Active | B5: 431 | C5: 50 | D5: 289 | E5: 180
A6: Canceled | B6: 116 | C6: 8 | D6: 73 | E6: 53
A7: Grand Total | B7: 547 | C7: 58 | D7: 362 | E7: 233

Sheet Arpu
A3: Row Labels | B3: Sum of ARPU | C3: Sum of Column1
A4: Apr | B4: 1208.98 | C4: 4
A5: Aug | B5: 1606.36 | C5: 8
A6: Feb | B6: 1328.68 | C6: 2
A7: Jan | B7: 1217.27 | C7: 1
A8: July | B8: 1299.33 | C8: 7
A9: June | B9: 1521.44 | C9: 6
A10: Mar | B10: 1319.98 | C10: 3
A11: May | B11: 1799.92 | C11: 5
A12: Sep | B12: 1520.19 | C12: 9
A13: Grand Total | B13: 12822.15 | C13: 45

Sheet Churn
A1: Subscription Status | B1: Canceled
A3: Row Labels | B3: Churn Count
A4: Mar | B4: 2
A5: Apr | B5: 8
A6: May | B6: 10
A7: Jun | B7: 10
A8: Jul | B8: 28
A9: Aug | B9: 34
A10: Sep | B10: 158
A11: Grand Total | B11: 250
